Workbook

Sheet FS & Trend Analysis
A2: Financial Statements of Diageo Ltd. | I2: Trend Analysis
A4: Income Statement | I4: Income Statement
A5: Particulars (Amount in Crores of INR) | B5: 46112 | C5: 45747 | D5: 45382 | E5: 45016 | F5: 44651 | G5: 44286 | I5: Particulars | J5: 46112 | K5: 45747 | L5: 45382 | M5: 45016 | N5: 44651 | O5: 44286
A6: Revenue from Operations | B6: 27781 | C6: 26780 | D6: 25389 | E6: 27578 | F6: 30773 | G6: 27176.4 | I6: Revenue from Operations | J6: =B6/$G6 -> 1.0222472 | K6: =C6/$G6 -> 0.98541381 | L6: =D6/$G6 -> 0.9342297 | M6: =E6/$G6 -> 1.0147775 | N6: =F6/$G6 -> 1.1323428 | O6: =G6/$G6 -> 1
A7: Other Income | B7: 576 | C7: 426 | D7: 335 | E7: 74 | F7: 34 | G7: 47.8 | I7: Other Income | J7: =B7/$G7 -> 12.050209 | K7: =C7/$G7 -> 8.9121339 | L7: =D7/$G7 -> 7.0083682 | M7: =E7/$G7 -> 1.5481172 | N7: =F7/$G7 -> 0.71129707 | O7: =G7/$G7 -> 1
A8: Total Income | B8: =SUM(B6:B7) -> 28357 | C8: =SUM(C6:C7) -> 27206 | D8: =SUM(D6:D7) -> 25724 | E8: =SUM(E6:E7) -> 27652 | F8: =SUM(F6:F7) -> 30807 | G8: =SUM(G6:G7) -> 27224.2 | I8: Total Income | J8: =B8/$G8 -> 1.04161 | K8: =C8/$G8 -> 0.99933148 | L8: =D8/$G8 -> 0.94489462 | M8: =E8/$G8 -> 1.015714 | N8: =F8/$G8 -> 1.1316035 | O8: =G8/$G8 -> 1
A10: Expenses | I10: Expenses
A11: Cost of materials consumed | B11: 5998 | C11: 5443 | D11: 5254 | E11: 5337 | F11: 4789 | G11: 3988.6 | I11: Cost of materials consumed | J11: =B11/$G11 -> 1.5037858 | K11: =C11/$G11 -> 1.3646392 | L11: =D11/$G11 -> 1.3172542 | M11: =E11/$G11 -> 1.3380635 | N11: =F11/$G11 -> 1.2006719 | O11: =G11/$G11 -> 1
A12: Purchase of stock-in-trade | B12: 808 | C12: 864 | D12: 675 | E12: 864 | F12: 577 | G12: 349.4 | I12: Purchase of stock-in-trade | J12: =B12/$G12 -> 2.3125358 | K12: =C12/$G12 -> 2.4728105 | L12: =D12/$G12 -> 1.9318832 | M12: =E12/$G12 -> 2.4728105 | N12: =F12/$G12 -> 1.6514024 | O12: =G12/$G12 -> 1
A13: Change in inventories of finished goods, work-in-progress and stock-in-trade | B13: -140 | C13: 90 | D13: 119 | E13: -129 | F13: -82.8 | G13: 130.2 | I13: Change in inventories of finished goods, work-in-progress and stock-in-trade | J13: =B13/$G13 -> -1.0752688 | K13: =C13/$G13 -> 0.69124424 | L13: =D13/$G13 -> 0.91397849 | M13: =E13/$G13 -> -0.99078341 | N13: =F13/$G13 -> -0.6359447 | O13: =G13/$G13 -> 1
A14: Excise duty | B14: 15333 | C14: 15207 | D14: 14697 | E14: 17204 | F14: 21349 | G14: 19287.2 | I14: Excise duty | J14: =B14/$G14 -> 0.7949832 | K14: =C14/$G14 -> 0.78845037 | L14: =D14/$G14 -> 0.76200796 | M14: =E14/$G14 -> 0.89199054 | N14: =F14/$G14 -> 1.1068999 | O14: =G14/$G14 -> 1
A15: Employee benefits expense | B15: 623 | C15: 605 | D15: 543 | E15: 607 | F15: 650 | G15: 540.4 | I15: Employee benefits expense | J15: =B15/$G15 -> 1.1528497 | K15: =C15/$G15 -> 1.1195411 | L15: =D15/$G15 -> 1.0048113 | M15: =E15/$G15 -> 1.123242 | N15: =F15/$G15 -> 1.2028127 | O15: =G15/$G15 -> 1
A16: Advertisement and sales promotion | B16: 1295 | C16: 1128 | D16: 1041 | E16: 920 | F16: 689 | G16: 571.6 | I16: Advertisement and sales promotion | J16: =B16/$G16 -> 2.2655703 | K16: =C16/$G16 -> 1.973408 | L16: =D16/$G16 -> 1.8212036 | M16: =E16/$G16 -> 1.6095171 | N16: =F16/$G16 -> 1.2053884 | O16: =G16/$G16 -> 1
A17: Other expenses | B17: 1568 | C17: 1385 | D17: 1352 | E17: 1356 | F17: 1303 | G17: 1272.9 | I17: Other expenses | J17: =B17/$G17 -> 1.2318328 | K17: =C17/$G17 -> 1.0880666 | L17: =D17/$G17 -> 1.0621416 | M17: =E17/$G17 -> 1.065284 | N17: =F17/$G17 -> 1.0236468 | O17: =G17/$G17 -> 1
A18: Total expenses | B18: =SUM(B11:B17) -> 25485 | C18: =SUM(C11:C17) -> 24722 | D18: =SUM(D11:D17) -> 23681 | E18: =SUM(E11:E17) -> 26159 | F18: =SUM(F11:F17) -> 29274.2 | G18: =SUM(G11:G17) -> 26140.3 | I18: Total expenses | J18: =B18/$G18 -> 0.97493143 | K18: =C18/$G18 -> 0.94574278 | L18: =D18/$G18 -> 0.90591921 | M18: =E18/$G18 -> 1.0007154 | N18: =F18/$G18 -> 1.1198877 | O18: =G18/$G18 -> 1
A20: EBITDA | B20: =B8-B18 -> 2872 | C20: =C8-C18 -> 2484 | D20: =D8-D18 -> 2043 | E20: =E8-E18 -> 1493 | F20: =F8-F18 -> 1532.8 | G20: =G8-G18 -> 1083.9 | I20: EBITDA | J20: =B20/$G20 -> 2.6496909 | K20: =C20/$G20 -> 2.2917243 | L20: =D20/$G20 -> 1.8848602 | M20: =E20/$G20 -> 1.3774333 | N20: =F20/$G20 -> 1.4141526 | O20: =G20/$G20 -> 1
A21: Depreciation and amortisation expense | B21: 283 | C21: 274 | D21: 264 | E21: 271 | F21: 289 | G21: 249.3 | I21: Depreciation and amortisation expense | J21: =B21/$G21 -> 1.1351785 | K21: =C21/$G21 -> 1.0990774 | L21: =D21/$G21 -> 1.0589651 | M21: =E21/$G21 -> 1.0870437 | N21: =F21/$G21 -> 1.1592459 | O21: =G21/$G21 -> 1
A22: EBIT | B22: =B20-B21 -> 2589 | C22: =C20-C21 -> 2210 | D22: =D20-D21 -> 1779 | E22: =E20-E21 -> 1222 | F22: =F20-F21 -> 1243.8 | G22: =G20-G21 -> 834.6 | I22: EBIT | J22: =B22/$G22 -> 3.1020848 | K22: =C22/$G22 -> 2.6479751 | L22: =D22/$G22 -> 2.13156 | M22: =E22/$G22 -> 1.4641745 | N22: =F22/$G22 -> 1.4902948 | O22: =G22/$G22 -> 1
A23: Finance costs | B23: 158 | C23: 89 | D23: 76 | E23: 104 | F23: 88 | G23: 165.8 | I23: Finance costs | J23: =B23/$G23 -> 0.95295537 | K23: =C23/$G23 -> 0.53679131 | L23: =D23/$G23 -> 0.45838359 | M23: =E23/$G23 -> 0.62726176 | N23: =F23/$G23 -> 0.53075995 | O23: =G23/$G23 -> 1
A24: PBT before profits of JVs | B24: =B22-B23 -> 2431 | C24: =C22-C23 -> 2121 | D24: =D22-D23 -> 1703 | E24: =E22-E23 -> 1118 | F24: =F22-F23 -> 1155.8 | G24: =G22-G23 -> 668.8 | I24: PBT before profits of JVs | J24: =B24/$G24 -> 3.6348684 | K24: =C24/$G24 -> 3.1713517 | L24: =D24/$G24 -> 2.5463517 | M24: =E24/$G24 -> 1.6716507 | N24: =F24/$G24 -> 1.7281699 | O24: =G24/$G24 -> 1
A25: Add: Share of Profits of JVs | B25: 0 | C25: 0 | D25: 0 | E25: 0 | F25: 0 | G25: 0 | I25: Add: Share of Profits of JVs
A26: PBT & Exceptional Items | B26: =SUM(B24:B25) -> 2431 | C26: =SUM(C24:C25) -> 2121 | D26: =SUM(D24:D25) -> 1703 | E26: =SUM(E24:E25) -> 1118 | F26: =SUM(F24:F25) -> 1155.8 | G26: =SUM(G24:G25) -> 668.8 | I26: PBT & Exceptional Items | J26: =B26/$G26 -> 3.6348684 | K26: =C26/$G26 -> 3.1713517 | L26: =D26/$G26 -> 2.5463517 | M26: =E26/$G26 -> 1.6716507 | N26: =F26/$G26 -> 1.7281699 | O26: =G26/$G26 -> 1
A27: Exceptional Items | B27: -91 | C27: -65 | D27: -17 | E27: 171 | F27: -156 | G27: -151.4 | I27: Exceptional Items | J27: =B27/$G27 -> 0.6010568 | K27: =C27/$G27 -> 0.42932629 | L27: =D27/$G27 -> 0.11228534 | M27: =E27/$G27 -> -1.1294584 | N27: =F27/$G27 -> 1.0303831 | O27: =G27/$G27 -> 1
A28: PBT | B28: =B26+B27 -> 2340 | C28: =C26+C27 -> 2056 | D28: =D26+D27 -> 1686 | E28: =E26+E27 -> 1289 | F28: =F26+F27 -> 999.8 | G28: =G26+G27 -> 517.4 | I28: PBT | J28: =B28/$G28 -> 4.5226131 | K28: =C28/$G28 -> 3.9737147 | L28: =D28/$G28 -> 3.2586007 | M28: =E28/$G28 -> 2.4913027 | N28: =F28/$G28 -> 1.9323541 | O28: =G28/$G28 -> 1
A29: Tax | B29: 510 | C29: 498 | D29: 374 | E29: 237 | F29: 160 | G29: 158.7 | I29: Tax | J29: =B29/$G29 -> 3.2136106 | K29: =C29/$G29 -> 3.1379962 | L29: =D29/$G29 -> 2.3566478 | M29: =E29/$G29 -> 1.4933837 | N29: =F29/$G29 -> 1.0081916 | O29: =G29/$G29 -> 1
A30: PAT | B30: =B28-B29 -> 1830 | C30: =C28-C29 -> 1558 | D30: =D28-D29 -> 1312 | E30: =E28-E29 -> 1052 | F30: =F28-F29 -> 839.8 | G30: =G28-G29 -> 358.7 | I30: PAT | J30: =B30/$G30 -> 5.1017563 | K30: =C30/$G30 -> 4.3434625 | L30: =D30/$G30 -> 3.6576526 | M30: =E30/$G30 -> 2.9328129 | N30: =F30/$G30 -> 2.3412322 | O30: =G30/$G30 -> 1
A31: Less: Share of Minority Interest | B31: 0 | C31: 0 | D31: 0 | E31: 0 | F31: 0 | G31: 0 | I31: Less: Share of Minority Interest
A32: PAT for Equity Shareholders | B32: =B30-B31 -> 1830 | C32: =C30-C31 -> 1558 | D32: =D30-D31 -> 1312 | E32: =E30-E31 -> 1052 | F32: =F30-F31 -> 839.8 | G32: =G30-G31 -> 358.7 | I32: PAT for Equity Shareholders | J32: =B32/$G32 -> 5.1017563 | K32: =C32/$G32 -> 4.3434625 | L32: =D32/$G32 -> 3.6576526 | M32: =E32/$G32 -> 2.9328129 | N32: =F32/$G32 -> 2.3412322 | O32: =G32/$G32 -> 1
A33: Dividend | B33: 1263 | C33: 350 | D33: 291 | E33: 0 | F33: 0 | G33: 0 | I33: Dividend
A34: Tax Rate (%) | B34: =B29/B28 -> 0.21794872 | C34: =C29/C28 -> 0.2422179 | D34: =D29/D28 -> 0.22182681 | E34: =E29/E28 -> 0.18386346 | F34: =F29/F28 -> 0.16003201 | G34: =G29/G28 -> 0.30672594 | I34: Tax Rate (%)
A37: Balance Sheet | I37: Balance Sheet
A38: Particulars | B38: 46112 | C38: 45747 | D38: 45382 | E38: 45016 | F38: 44651 | G38: 44286 | I38: Particulars | J38: 46112 | K38: 45747 | L38: 45382 | M38: 45016 | N38: 44651 | O38: 44286
A39: Equity & Liabilities | I39: Equity & Liabilities
A40: Share capital | B40: 145 | C40: 145 | D40: 145 | E40: 145.5 | F40: 145.5 | G40: 145.3 | I40: Share capital | J40: =B40/$G40 -> 0.99793531 | K40: =C40/$G40 -> 0.99793531 | L40: =D40/$G40 -> 0.99793531 | M40: =E40/$G40 -> 1.0013765 | N40: =F40/$G40 -> 1.0013765 | O40: =G40/$G40 -> 1
A41: Share suspense | B41: 0 | C41: 0 | D41: 0 | E41: 0 | F41: 0.2 | G41: 0 | I41: Share suspense
A42: Other equity | I42: Other equity
A43: Reserves and surplus | B43: 8576 | C43: 7734 | D43: 6818 | E43: 5799 | F43: 4746.8 | G43: 3981.5 | I43: Reserves and surplus | J43: =B43/$G43 -> 2.1539621 | K43: =C43/$G43 -> 1.942484 | L43: =D43/$G43 -> 1.7124199 | M43: =E43/$G43 -> 1.4564862 | N43: =F43/$G43 -> 1.192214 | O43: =G43/$G43 -> 1
A44: Total Equity | B44: =SUM(B40:B43) -> 8721 | C44: =SUM(C40:C43) -> 7879 | D44: =SUM(D40:D43) -> 6963 | E44: =SUM(E40:E43) -> 5944.5 | F44: =SUM(F40:F43) -> 4892.5 | G44: =SUM(G40:G43) -> 4126.8 | I44: Total Equity | J44: =B44/$G44 -> 2.1132597 | K44: =C44/$G44 -> 1.9092275 | L44: =D44/$G44 -> 1.6872637 | M44: =E44/$G44 -> 1.4404623 | N44: =F44/$G44 -> 1.1855433 | O44: =G44/$G44 -> 1
A46: Non-Current Liabilities | I46: Non-Current Liabilities
A47: Borrowings | B47: 0 | C47: 0 | D47: 0 | E47: 0.3 | F47: 0.9 | G47: 0 | I47: Borrowings
...

Sheet Sheet1
A1: 44651 | B1: 45016 | C1: 45382 | D1: 45747 | E1: 46112
A2: 30773 | B2: 27578 | C2: 25389 | D2: 26780 | E2: 27781
A3: 34 | B3: 74 | C3: 335 | D3: 426 | E3: 576
A4: =SUM(A2:A3) -> 30807 | B4: =SUM(B2:B3) -> 27652 | C4: =SUM(C2:C3) -> 25724 | D4: =SUM(D2:D3) -> 27206 | E4: =SUM(E2:E3) -> 28357
A7: 4789 | B7: 5337 | C7: 5254 | D7: 5443 | E7: 5998
A8: 577 | B8: 864 | C8: 675 | D8: 864 | E8: 808
A9: -82.8 | B9: -129 | C9: 119 | D9: 90 | E9: -140
A10: 21349 | B10: 17204 | C10: 14697 | D10: 15207 | E10: 15333
A11: 650 | B11: 607 | C11: 543 | D11: 605 | E11: 623
A12: 689 | B12: 920 | C12: 1041 | D12: 1128 | E12: 1295
A13: 1303 | B13: 1356 | C13: 1352 | D13: 1385 | E13: 1568
A14: =SUM(A7:A13) -> 29274.2 | B14: =SUM(B7:B13) -> 26159 | C14: =SUM(C7:C13) -> 23681 | D14: =SUM(D7:D13) -> 24722 | E14: =SUM(E7:E13) -> 25485
A16: =A4-A14 -> 1532.8 | B16: =B4-B14 -> 1493 | C16: =C4-C14 -> 2043 | D16: =D4-D14 -> 2484 | E16: =E4-E14 -> 2872
A17: 289 | B17: 271 | C17: 264 | D17: 274 | E17: 283
A18: =A16-A17 -> 1243.8 | B18: =B16-B17 -> 1222 | C18: =C16-C17 -> 1779 | D18: =D16-D17 -> 2210 | E18: =E16-E17 -> 2589
A19: 88 | B19: 104 | C19: 76 | D19: 89 | E19: 158
A20: =A18-A19 -> 1155.8 | B20: =B18-B19 -> 1118 | C20: =C18-C19 -> 1703 | D20: =D18-D19 -> 2121 | E20: =E18-E19 -> 2431
A21: 0 | B21: 0 | C21: 0 | D21: 0 | E21: 0
A22: =SUM(A20:A21) -> 1155.8 | B22: =SUM(B20:B21) -> 1118 | C22: =SUM(C20:C21) -> 1703 | D22: =SUM(D20:D21) -> 2121 | E22: =SUM(E20:E21) -> 2431
A23: -156 | B23: 171 | C23: -17 | D23: -65 | E23: -91
A24: =A22+A23 -> 999.8 | B24: =B22+B23 -> 1289 | C24: =C22+C23 -> 1686 | D24: =D22+D23 -> 2056 | E24: =E22+E23 -> 2340
A25: 160 | B25: 237 | C25: 374 | D25: 498 | E25: 510
A26: =A24-A25 -> 839.8 | B26: =B24-B25 -> 1052 | C26: =C24-C25 -> 1312 | D26: =D24-D25 -> 1558 | E26: =E24-E25 -> 1830
A27: 0 | B27: 0 | C27: 0 | D27: 0 | E27: 0
A28: =A26-A27 -> 839.8 | B28: =B26-B27 -> 1052 | C28: =C26-C27 -> 1312 | D28: =D26-D27 -> 1558 | E28: =E26-E27 -> 1830
A29: 0 | B29: 0 | C29: 291 | D29: 350 | E29: 1263
A30: =A25/A24 -> 0.16003201 | B30: =B25/B24 -> 0.18386346 | C30: =C25/C24 -> 0.22182681 | D30: =D25/D24 -> 0.2422179 | E30: =E25/E24 -> 0.21794872

Sheet Common Size FS
A2: Common Size statement
A4: Income Statement
A5: Particulars | B5: 46112 | C5: 45747 | D5: 45382 | E5: 45016 | F5: 44651 | G5: 44286
A6: Revenue from Operations | B6: ='FS & Trend Analysis'!B6/'FS & Trend Analysis'!B$6 -> 1 | C6: ='FS & Trend Analysis'!C6/'FS & Trend Analysis'!C$6 -> 1 | D6: ='FS & Trend Analysis'!D6/'FS & Trend Analysis'!D$6 -> 1 | E6: ='FS & Trend Analysis'!E6/'FS & Trend Analysis'!E$6 -> 1 | F6: ='FS & Trend Analysis'!F6/'FS & Trend Analysis'!F$6 -> 1 | G6: ='FS & Trend Analysis'!G6/'FS & Trend Analysis'!G$6 -> 1
A7: Other Income | B7: ='FS & Trend Analysis'!B7/'FS & Trend Analysis'!B$6 -> 0.020733595 | C7: ='FS & Trend Analysis'!C7/'FS & Trend Analysis'!C$6 -> 0.015907394 | D7: ='FS & Trend Analysis'!D7/'FS & Trend Analysis'!D$6 -> 0.013194691 | E7: ='FS & Trend Analysis'!E7/'FS & Trend Analysis'!E$6 -> 0.0026832983 | F7: ='FS & Trend Analysis'!F7/'FS & Trend Analysis'!F$6 -> 0.0011048647 | G7: ='FS & Trend Analysis'!G7/'FS & Trend Analysis'!G$6 -> 0.001758879
A8: Total Income | B8: ='FS & Trend Analysis'!B8/'FS & Trend Analysis'!B$6 -> 1.0207336 | C8: ='FS & Trend Analysis'!C8/'FS & Trend Analysis'!C$6 -> 1.0159074 | D8: ='FS & Trend Analysis'!D8/'FS & Trend Analysis'!D$6 -> 1.0131947 | E8: ='FS & Trend Analysis'!E8/'FS & Trend Analysis'!E$6 -> 1.0026833 | F8: ='FS & Trend Analysis'!F8/'FS & Trend Analysis'!F$6 -> 1.0011049 | G8: ='FS & Trend Analysis'!G8/'FS & Trend Analysis'!G$6 -> 1.0017589
A10: Expenses
A11: Raw Material | B11: ='FS & Trend Analysis'!B11/'FS & Trend Analysis'!B$6 -> 0.21590296 | C11: ='FS & Trend Analysis'!C11/'FS & Trend Analysis'!C$6 -> 0.20324869 | D11: ='FS & Trend Analysis'!D11/'FS & Trend Analysis'!D$6 -> 0.20694001 | E11: ='FS & Trend Analysis'!E11/'FS & Trend Analysis'!E$6 -> 0.19352382 | F11: ='FS & Trend Analysis'!F11/'FS & Trend Analysis'!F$6 -> 0.15562344 | G11: ='FS & Trend Analysis'!G11/'FS & Trend Analysis'!G$6 -> 0.14676705
A12: Excise Duty | B12: ='FS & Trend Analysis'!B12/'FS & Trend Analysis'!B$6 -> 0.029084626 | C12: ='FS & Trend Analysis'!C12/'FS & Trend Analysis'!C$6 -> 0.032262883 | D12: ='FS & Trend Analysis'!D12/'FS & Trend Analysis'!D$6 -> 0.026586317 | E12: ='FS & Trend Analysis'!E12/'FS & Trend Analysis'!E$6 -> 0.03132932 | F12: ='FS & Trend Analysis'!F12/'FS & Trend Analysis'!F$6 -> 0.018750203 | G12: ='FS & Trend Analysis'!G12/'FS & Trend Analysis'!G$6 -> 0.012856743
A13: Employee Costs | B13: ='FS & Trend Analysis'!B13/'FS & Trend Analysis'!B$6 -> -0.0050394154 | C13: ='FS & Trend Analysis'!C13/'FS & Trend Analysis'!C$6 -> 0.003360717 | D13: ='FS & Trend Analysis'!D13/'FS & Trend Analysis'!D$6 -> 0.0046870692 | E13: ='FS & Trend Analysis'!E13/'FS & Trend Analysis'!E$6 -> -0.0046776416 | F13: ='FS & Trend Analysis'!F13/'FS & Trend Analysis'!F$6 -> -0.0026906704 | G13: ='FS & Trend Analysis'!G13/'FS & Trend Analysis'!G$6 -> 0.0047909215
A14: Other Expenses | B14: ='FS & Trend Analysis'!B14/'FS & Trend Analysis'!B$6 -> 0.55192398 | C14: ='FS & Trend Analysis'!C14/'FS & Trend Analysis'!C$6 -> 0.56784914 | D14: ='FS & Trend Analysis'!D14/'FS & Trend Analysis'!D$6 -> 0.57887274 | E14: ='FS & Trend Analysis'!E14/'FS & Trend Analysis'!E$6 -> 0.62383059 | F14: ='FS & Trend Analysis'!F14/'FS & Trend Analysis'!F$6 -> 0.69375751 | G14: ='FS & Trend Analysis'!G14/'FS & Trend Analysis'!G$6 -> 0.70970401
A15: Total Expenses | B15: ='FS & Trend Analysis'!B15/'FS & Trend Analysis'!B$6 -> 0.022425399 | C15: ='FS & Trend Analysis'!C15/'FS & Trend Analysis'!C$6 -> 0.022591486 | D15: ='FS & Trend Analysis'!D15/'FS & Trend Analysis'!D$6 -> 0.021387215 | E15: ='FS & Trend Analysis'!E15/'FS & Trend Analysis'!E$6 -> 0.022010298 | F15: ='FS & Trend Analysis'!F15/'FS & Trend Analysis'!F$6 -> 0.021122413 | G15: ='FS & Trend Analysis'!G15/'FS & Trend Analysis'!G$6 -> 0.0198849
B16: ='FS & Trend Analysis'!B16/'FS & Trend Analysis'!B$6 -> 0.046614593 | C16: ='FS & Trend Analysis'!C16/'FS & Trend Analysis'!C$6 -> 0.042120986 | D16: ='FS & Trend Analysis'!D16/'FS & Trend Analysis'!D$6 -> 0.041002009 | E16: ='FS & Trend Analysis'!E16/'FS & Trend Analysis'!E$6 -> 0.033359925 | F16: ='FS & Trend Analysis'!F16/'FS & Trend Analysis'!F$6 -> 0.022389757 | G16: ='FS & Trend Analysis'!G16/'FS & Trend Analysis'!G$6 -> 0.021032955
A17: EBITDA | B17: ='FS & Trend Analysis'!B17/'FS & Trend Analysis'!B$6 -> 0.056441453 | C17: ='FS & Trend Analysis'!C17/'FS & Trend Analysis'!C$6 -> 0.0517177 | D17: ='FS & Trend Analysis'!D17/'FS & Trend Analysis'!D$6 -> 0.053251408 | E17: ='FS & Trend Analysis'!E17/'FS & Trend Analysis'!E$6 -> 0.049169628 | F17: ='FS & Trend Analysis'!F17/'FS & Trend Analysis'!F$6 -> 0.042342313 | G17: ='FS & Trend Analysis'!G17/'FS & Trend Analysis'!G$6 -> 0.046838433
A18: Depreciation & Amortization | B18: ='FS & Trend Analysis'!B18/'FS & Trend Analysis'!B$6 -> 0.91735359 | C18: ='FS & Trend Analysis'!C18/'FS & Trend Analysis'!C$6 -> 0.92315161 | D18: ='FS & Trend Analysis'!D18/'FS & Trend Analysis'!D$6 -> 0.93272677 | E18: ='FS & Trend Analysis'!E18/'FS & Trend Analysis'!E$6 -> 0.94854594 | F18: ='FS & Trend Analysis'!F18/'FS & Trend Analysis'!F$6 -> 0.95129497 | G18: ='FS & Trend Analysis'!G18/'FS & Trend Analysis'!G$6 -> 0.96187501
A19: EBIT | B19: ='FS & Trend Analysis'!B19/'FS & Trend Analysis'!B$6 -> 0 | C19: ='FS & Trend Analysis'!C19/'FS & Trend Analysis'!C$6 -> 0 | D19: ='FS & Trend Analysis'!D19/'FS & Trend Analysis'!D$6 -> 0 | E19: ='FS & Trend Analysis'!E19/'FS & Trend Analysis'!E$6 -> 0 | F19: ='FS & Trend Analysis'!F19/'FS & Trend Analysis'!F$6 -> 0 | G19: ='FS & Trend Analysis'!G19/'FS & Trend Analysis'!G$6 -> 0
A20: Finance Expenses | B20: ='FS & Trend Analysis'!B20/'FS & Trend Analysis'!B$6 -> 0.10338001 | C20: ='FS & Trend Analysis'!C20/'FS & Trend Analysis'!C$6 -> 0.092755788 | D20: ='FS & Trend Analysis'!D20/'FS & Trend Analysis'!D$6 -> 0.080467919 | E20: ='FS & Trend Analysis'!E20/'FS & Trend Analysis'!E$6 -> 0.054137356 | F20: ='FS & Trend Analysis'!F20/'FS & Trend Analysis'!F$6 -> 0.049809898 | G20: ='FS & Trend Analysis'!G20/'FS & Trend Analysis'!G$6 -> 0.03988387
A21: PBT before profits of JVs | B21: ='FS & Trend Analysis'!B21/'FS & Trend Analysis'!B$6 -> 0.010186818 | C21: ='FS & Trend Analysis'!C21/'FS & Trend Analysis'!C$6 -> 0.010231516 | D21: ='FS & Trend Analysis'!D21/'FS & Trend Analysis'!D$6 -> 0.010398204 | E21: ='FS & Trend Analysis'!E21/'FS & Trend Analysis'!E$6 -> 0.0098266734 | F21: ='FS & Trend Analysis'!F21/'FS & Trend Analysis'!F$6 -> 0.0093913496 | G21: ='FS & Trend Analysis'!G21/'FS & Trend Analysis'!G$6 -> 0.0091734005
A22: Add: Share of Profits of JVs | B22: ='FS & Trend Analysis'!B22/'FS & Trend Analysis'!B$6 -> 0.09319319 | C22: ='FS & Trend Analysis'!C22/'FS & Trend Analysis'!C$6 -> 0.082524272 | D22: ='FS & Trend Analysis'!D22/'FS & Trend Analysis'!D$6 -> 0.070069715 | E22: ='FS & Trend Analysis'!E22/'FS & Trend Analysis'!E$6 -> 0.044310682 | F22: ='FS & Trend Analysis'!F22/'FS & Trend Analysis'!F$6 -> 0.040418549 | G22: ='FS & Trend Analysis'!G22/'FS & Trend Analysis'!G$6 -> 0.030710469
A23: PBT & Exceptional Items | B23: ='FS & Trend Analysis'!B23/'FS & Trend Analysis'!B$6 -> 0.0056873403 | C23: ='FS & Trend Analysis'!C23/'FS & Trend Analysis'!C$6 -> 0.0033233757 | D23: ='FS & Trend Analysis'!D23/'FS & Trend Analysis'!D$6 -> 0.0029934223 | E23: ='FS & Trend Analysis'!E23/'FS & Trend Analysis'!E$6 -> 0.0037711219 | F23: ='FS & Trend Analysis'!F23/'FS & Trend Analysis'!F$6 -> 0.0028596497 | G23: ='FS & Trend Analysis'!G23/'FS & Trend Analysis'!G$6 -> 0.0061008816
A24: Exceptional Items | B24: ='FS & Trend Analysis'!B24/'FS & Trend Analysis'!B$6 -> 0.087505849 | C24: ='FS & Trend Analysis'!C24/'FS & Trend Analysis'!C$6 -> 0.079200896 | D24: ='FS & Trend Analysis'!D24/'FS & Trend Analysis'!D$6 -> 0.067076293 | E24: ='FS & Trend Analysis'!E24/'FS & Trend Analysis'!E$6 -> 0.040539561 | F24: ='FS & Trend Analysis'!F24/'FS & Trend Analysis'!F$6 -> 0.037558899 | G24: ='FS & Trend Analysis'!G24/'FS & Trend Analysis'!G$6 -> 0.024609588
A25: PBT | B25: ='FS & Trend Analysis'!B25/'FS & Trend Analysis'!B$6 -> 0 | C25: ='FS & Trend Analysis'!C25/'FS & Trend Analysis'!C$6 -> 0 | D25: ='FS & Trend Analysis'!D25/'FS & Trend Analysis'!D$6 -> 0 | E25: ='FS & Trend Analysis'!E25/'FS & Trend Analysis'!E$6 -> 0 | F25: ='FS & Trend Analysis'!F25/'FS & Trend Analysis'!F$6 -> 0 | G25: ='FS & Trend Analysis'!G25/'FS & Trend Analysis'!G$6 -> 0
A26: Tax | B26: ='FS & Trend Analysis'!B26/'FS & Trend Analysis'!B$6 -> 0.087505849 | C26: ='FS & Trend Analysis'!C26/'FS & Trend Analysis'!C$6 -> 0.079200896 | D26: ='FS & Trend Analysis'!D26/'FS & Trend Analysis'!D$6 -> 0.067076293 | E26: ='FS & Trend Analysis'!E26/'FS & Trend Analysis'!E$6 -> 0.040539561 | F26: ='FS & Trend Analysis'!F26/'FS & Trend Analysis'!F$6 -> 0.037558899 | G26: ='FS & Trend Analysis'!G26/'FS & Trend Analysis'!G$6 -> 0.024609588
A27: PAT | B27: ='FS & Trend Analysis'!B27/'FS & Trend Analysis'!B$6 -> -0.00327562 | C27: ='FS & Trend Analysis'!C27/'FS & Trend Analysis'!C$6 -> -0.0024271845 | D27: ='FS & Trend Analysis'!D27/'FS & Trend Analysis'!D$6 -> -0.00066958131 | E27: ='FS & Trend Analysis'!E27/'FS & Trend Analysis'!E$6 -> 0.0062005947 | F27: ='FS & Trend Analysis'!F27/'FS & Trend Analysis'!F$6 -> -0.005069379 | G27: ='FS & Trend Analysis'!G27/'FS & Trend Analysis'!G$6 -> -0.0055710101
A28: Less: Share of Minority Interest | B28: ='FS & Trend Analysis'!B28/'FS & Trend Analysis'!B$6 -> 0.084230229 | C28: ='FS & Trend Analysis'!C28/'FS & Trend Analysis'!C$6 -> 0.076773712 | D28: ='FS & Trend Analysis'!D28/'FS & Trend Analysis'!D$6 -> 0.066406712 | E28: ='FS & Trend Analysis'!E28/'FS & Trend Analysis'!E$6 -> 0.046740155 | F28: ='FS & Trend Analysis'!F28/'FS & Trend Analysis'!F$6 -> 0.03248952 | G28: ='FS & Trend Analysis'!G28/'FS & Trend Analysis'!G$6 -> 0.019038578
... A30: Dividend | B30: ='FS & Trend Analysis'!B30/'FS & Trend Analysis'!B$6 -> 0.065872359 | C30: ='FS & Trend Analysis'!C30/'FS & Trend Analysis'!C$6 -> 0.058177745 | D30: ='FS & Trend Analysis'!D30/'FS & Trend Analysis'!D$6 -> 0.051675923 | E30: ='FS & Trend Analysis'!E30/'FS & Trend Analysis'!E$6 -> 0.038146349 | F30: ='FS & Trend Analysis'!F30/'FS & Trend Analysis'!F$6 -> 0.027290157 | G30: ='FS & Trend Analysis'!G30/'FS & Trend Analysis'!G$6 -> 0.013198952
A33: Balance Sheet
A34: Particulars | B34: 46112 | C34: 45747 | D34: 45382 | E34: 45016 | F34: 44651 | G34: 44286
A35: Equity & Liabilities
A36: Share capital | B36: ='FS & Trend Analysis'!B40/'FS & Trend Analysis'!B$62 -> 0.010458742 | C36: ='FS & Trend Analysis'!C40/'FS & Trend Analysis'!C$62 -> 0.011401164 | D36: ='FS & Trend Analysis'!D40/'FS & Trend Analysis'!D$62 -> 0.013497412 | E36: ='FS & Trend Analysis'!E40/'FS & Trend Analysis'!E$62 -> 0.015201538 | F36: ='FS & Trend Analysis'!F40/'FS & Trend Analysis'!F$62 -> 0.016680232 | G36: ='FS & Trend Analysis'!G40/'FS & Trend Analysis'!G$62 -> 0.017847492
A37: Share suspense | B37: ='FS & Trend Analysis'!B41/'FS & Trend Analysis'!B$62 -> 0 | C37: ='FS & Trend Analysis'!C41/'FS & Trend Analysis'!C$62 -> 0 | D37: ='FS & Trend Analysis'!D41/'FS & Trend Analysis'!D$62 -> 0 | E37: ='FS & Trend Analysis'!E41/'FS & Trend Analysis'!E$62 -> 0 | F37: ='FS & Trend Analysis'!F41/'FS & Trend Analysis'!F$62 -> 2.2928155e-05 | G37: ='FS & Trend Analysis'!G41/'FS & Trend Analysis'!G$62 -> 0
A38: Other equity | B38: ='FS & Trend Analysis'!B42/'FS & Trend Analysis'!B$62 -> 0 | C38: ='FS & Trend Analysis'!C42/'FS & Trend Analysis'!C$62 -> 0 | D38: ='FS & Trend Analysis'!D42/'FS & Trend Analysis'!D$62 -> 0 | E38: ='FS & Trend Analysis'!E42/'FS & Trend Analysis'!E$62 -> 0 | F38: ='FS & Trend Analysis'!F42/'FS & Trend Analysis'!F$62 -> 0 | G38: ='FS & Trend Analysis'!G42/'FS & Trend Analysis'!G$62 -> 0
A39: Reserves and surplus | B39: ='FS & Trend Analysis'!B43/'FS & Trend Analysis'!B$62 -> 0.6185805 | C39: ='FS & Trend Analysis'!C43/'FS & Trend Analysis'!C$62 -> 0.60811448 | D39: ='FS & Trend Analysis'!D43/'FS & Trend Analysis'!D$62 -> 0.63465763 | E39: ='FS & Trend Analysis'!E43/'FS & Trend Analysis'!E$62 -> 0.60586748 | F39: ='FS & Trend Analysis'!F43/'FS & Trend Analysis'!F$62 -> 0.54417682 | G39: ='FS & Trend Analysis'!G43/'FS & Trend Analysis'!G$62 -> 0.48905567
A40: Total Equity | B40: ='FS & Trend Analysis'!B44/'FS & Trend Analysis'!B$62 -> 0.62903924 | C40: ='FS & Trend Analysis'!C44/'FS & Trend Analysis'!C$62 -> 0.61951565 | D40: ='FS & Trend Analysis'!D44/'FS & Trend Analysis'!D$62 -> 0.64815504 | E40: ='FS & Trend Analysis'!E44/'FS & Trend Analysis'!E$62 -> 0.62106902 | F40: ='FS & Trend Analysis'!F44/'FS & Trend Analysis'!F$62 -> 0.56087998 | G40: ='FS & Trend Analysis'!G44/'FS & Trend Analysis'!G$62 -> 0.50690316
B41: ='FS & Trend Analysis'!B45/'FS & Trend Analysis'!B$62 -> 0 | C41: ='FS & Trend Analysis'!C45/'FS & Trend Analysis'!C$62 -> 0 | D41: ='FS & Trend Analysis'!D45/'FS & Trend Analysis'!D$62 -> 0 | E41: ='FS & Trend Analysis'!E45/'FS & Trend Analysis'!E$62 -> 0 | F41: ='FS & Trend Analysis'!F45/'FS & Trend Analysis'!F$62 -> 0 | G41: ='FS & Trend Analysis'!G45/'FS & Trend Analysis'!G$62 -> 0
A42: Non-Current Liabilities | B42: ='FS & Trend Analysis'!B46/'FS & Trend Analysis'!B$62 -> 0 | C42: ='FS & Trend Analysis'!C46/'FS & Trend Analysis'!C$62 -> 0 | D42: ='FS & Trend Analysis'!D46/'FS & Trend Analysis'!D$62 -> 0 | E42: ='FS & Trend Analysis'!E46/'FS & Trend Analysis'!E$62 -> 0 | F42: ='FS & Trend Analysis'!F46/'FS & Trend Analysis'!F$62 -> 0 | G42: ='FS & Trend Analysis'!G46/'FS & Trend Analysis'!G$62 -> 0
A43: Borrowings | B43: ='FS & Trend Analysis'!B47/'FS & Trend Analysis'!B$62 -> 0 | C43: ='FS & Trend Analysis'!C47/'FS & Trend Analysis'!C$62 -> 0 | D43: ='FS & Trend Analysis'!D47/'FS & Trend Analysis'!D$62 -> 0 | E43: ='FS & Trend Analysis'!E47/'FS & Trend Analysis'!E$62 -> 3.1343377e-05 | F43: ='FS & Trend Analysis'!F47/'FS & Trend Analysis'!F$62 -> 0.0001031767 | G43: ='FS & Trend Analysis'!G47/'FS & Trend Analysis'!G$62 -> 0
A44: Lease liabilities | B44: ='FS & Trend Analysis'!B48/'FS & Trend Analysis'!B$62 -> 0.022143681 | C44: ='FS & Trend Analysis'!C48/'FS & Trend Analysis'!C$62 -> 0.026261991 | D44: ='FS & Trend Analysis'!D48/'FS & Trend Analysis'!D$62 -> 0.012752727 | E44: ='FS & Trend Analysis'!E48/'FS & Trend Analysis'!E$62 -> 0.0083582339 | F44: ='FS & Trend Analysis'!F48/'FS & Trend Analysis'!F$62 -> 0.015373328 | G44: ='FS & Trend Analysis'!G48/'FS & Trend Analysis'!G$62 -> 0.011361961
A45: Provisions | B45: ='FS & Trend Analysis'!B49/'FS & Trend Analysis'!B$62 -> 0.002813041 | C45: ='FS & Trend Analysis'!C49/'FS & Trend Analysis'!C$62 -> 0.0012580594 | D45: ='FS & Trend Analysis'!D49/'FS & Trend Analysis'!D$62 -> 0.001396284 | E45: ='FS & Trend Analysis'!E49/'FS & Trend Analysis'!E$62 -> 0.0012850785 | F45: ='FS & Trend Analysis'!F49/'FS & Trend Analysis'!F$62 -> 0.0017081475 | G45: ='FS & Trend Analysis'!G49/'FS & Trend Analysis'!G$62 -> 0.00092124011
A46: Total Non-Current Liabilities | B46: ='FS & Trend Analysis'!B50/'FS & Trend Analysis'!B$62 -> 0.024956722 | C46: ='FS & Trend Analysis'!C50/'FS & Trend Analysis'!C$62 -> 0.02752005 | D46: ='FS & Trend Analysis'!D50/'FS & Trend Analysis'!D$62 -> 0.014149011 | E46: ='FS & Trend Analysis'!E50/'FS & Trend Analysis'!E$62 -> 0.0096746557 | F46: ='FS & Trend Analysis'!F50/'FS & Trend Analysis'!F$62 -> 0.017184652 | G46: ='FS & Trend Analysis'!G50/'FS & Trend Analysis'!G$62 -> 0.012283201
...

Sheet Comparative FS
B2: Comparative Financial Statements (YoY)
B4: Comparative Income Statement
B5: Particulars | C5: 46112 | D5: 45747 | E5: 45382 | F5: 45016 | G5: 44651
B6: Revenue from Operations | C6: =('FS & Trend Analysis'!B6-'FS & Trend Analysis'!C6)/'FS & Trend Analysis'!C6 -> 0.037378641 | D6: =('FS & Trend Analysis'!C6-'FS & Trend Analysis'!D6)/'FS & Trend Analysis'!D6 -> 0.054787506 | E6: =('FS & Trend Analysis'!D6-'FS & Trend Analysis'!E6)/'FS & Trend Analysis'!E6 -> -0.079374864 | F6: =('FS & Trend Analysis'!E6-'FS & Trend Analysis'!F6)/'FS & Trend Analysis'!F6 -> -0.10382478 | G6: =('FS & Trend Analysis'!F6-'FS & Trend Analysis'!G6)/'FS & Trend Analysis'!G6 -> 0.13234277
B7: Other Income | C7: =('FS & Trend Analysis'!B7-'FS & Trend Analysis'!C7)/'FS & Trend Analysis'!C7 -> 0.35211268 | D7: =('FS & Trend Analysis'!C7-'FS & Trend Analysis'!D7)/'FS & Trend Analysis'!D7 -> 0.27164179 | E7: =('FS & Trend Analysis'!D7-'FS & Trend Analysis'!E7)/'FS & Trend Analysis'!E7 -> 3.527027 | F7: =('FS & Trend Analysis'!E7-'FS & Trend Analysis'!F7)/'FS & Trend Analysis'!F7 -> 1.1764706 | G7: =('FS & Trend Analysis'!F7-'FS & Trend Analysis'!G7)/'FS & Trend Analysis'!G7 -> -0.28870293
B8: Total Income | C8: =('FS & Trend Analysis'!B8-'FS & Trend Analysis'!C8)/'FS & Trend Analysis'!C8 -> 0.042306844 | D8: =('FS & Trend Analysis'!C8-'FS & Trend Analysis'!D8)/'FS & Trend Analysis'!D8 -> 0.057611569 | E8: =('FS & Trend Analysis'!D8-'FS & Trend Analysis'!E8)/'FS & Trend Analysis'!E8 -> -0.069723709 | F8: =('FS & Trend Analysis'!E8-'FS & Trend Analysis'!F8)/'FS & Trend Analysis'!F8 -> -0.10241179 | G8: =('FS & Trend Analysis'!F8-'FS & Trend Analysis'!G8)/'FS & Trend Analysis'!G8 -> 0.1316035
B10: Expenses
B11: Cost of materials consumed | C11: =('FS & Trend Analysis'!B11-'FS & Trend Analysis'!C11)/'FS & Trend Analysis'!C11 -> 0.10196583 | D11: =('FS & Trend Analysis'!C11-'FS & Trend Analysis'!D11)/'FS & Trend Analysis'!D11 -> 0.035972592 | E11: =('FS & Trend Analysis'!D11-'FS & Trend Analysis'!E11)/'FS & Trend Analysis'!E11 -> -0.015551808 | F11: =('FS & Trend Analysis'!E11-'FS & Trend Analysis'!F11)/'FS & Trend Analysis'!F11 -> 0.1144289 | G11: =('FS & Trend Analysis'!F11-'FS & Trend Analysis'!G11)/'FS & Trend Analysis'!G11 -> 0.20067191
B12: Purchase of stock-in-trade | C12: =('FS & Trend Analysis'!B12-'FS & Trend Analysis'!C12)/'FS & Trend Analysis'!C12 -> -0.064814815 | D12: =('FS & Trend Analysis'!C12-'FS & Trend Analysis'!D12)/'FS & Trend Analysis'!D12 -> 0.28 | E12: =('FS & Trend Analysis'!D12-'FS & Trend Analysis'!E12)/'FS & Trend Analysis'!E12 -> -0.21875 | F12: =('FS & Trend Analysis'!E12-'FS & Trend Analysis'!F12)/'FS & Trend Analysis'!F12 -> 0.49740035 | G12: =('FS & Trend Analysis'!F12-'FS & Trend Analysis'!G12)/'FS & Trend Analysis'!G12 -> 0.6514024
B13: Change in inventories of finished goods, work-in-progress and stock-in-trade | C13: =('FS & Trend Analysis'!B13-'FS & Trend Analysis'!C13)/'FS & Trend Analysis'!C13 -> -2.5555556 | D13: =('FS & Trend Analysis'!C13-'FS & Trend Analysis'!D13)/'FS & Trend Analysis'!D13 -> -0.24369748 | E13: =('FS & Trend Analysis'!D13-'FS & Trend Analysis'!E13)/'FS & Trend Analysis'!E13 -> -1.9224806 | F13: =('FS & Trend Analysis'!E13-'FS & Trend Analysis'!F13)/'FS & Trend Analysis'!F13 -> 0.55797101 | G13: =('FS & Trend Analysis'!F13-'FS & Trend Analysis'!G13)/'FS & Trend Analysis'!G13 -> -1.6359447
B14: Excise duty | C14: =('FS & Trend Analysis'!B14-'FS & Trend Analysis'!C14)/'FS & Trend Analysis'!C14 -> 0.0082856579 | D14: =('FS & Trend Analysis'!C14-'FS & Trend Analysis'!D14)/'FS & Trend Analysis'!D14 -> 0.034700959 | E14: =('FS & Trend Analysis'!D14-'FS & Trend Analysis'!E14)/'FS & Trend Analysis'!E14 -> -0.14572193 | F14: =('FS & Trend Analysis'!E14-'FS & Trend Analysis'!F14)/'FS & Trend Analysis'!F14 -> -0.19415429 | G14: =('FS & Trend Analysis'!F14-'FS & Trend Analysis'!G14)/'FS & Trend Analysis'!G14 -> 0.10689991
B15: Employee benefits expense | C15: =('FS & Trend Analysis'!B15-'FS & Trend Analysis'!C15)/'FS & Trend Analysis'!C15 -> 0.029752066 | D15: =('FS & Trend Analysis'!C15-'FS & Trend Analysis'!D15)/'FS & Trend Analysis'!D15 -> 0.11418048 | E15: =('FS & Trend Analysis'!D15-'FS & Trend Analysis'!E15)/'FS & Trend Analysis'!E15 -> -0.10543657 | F15: =('FS & Trend Analysis'!E15-'FS & Trend Analysis'!F15)/'FS & Trend Analysis'!F15 -> -0.066153846 | G15: =('FS & Trend Analysis'!F15-'FS & Trend Analysis'!G15)/'FS & Trend Analysis'!G15 -> 0.20281273
B16: Advertisement and sales promotion | C16: =('FS & Trend Analysis'!B16-'FS & Trend Analysis'!C16)/'FS & Trend Analysis'!C16 -> 0.14804965 | D16: =('FS & Trend Analysis'!C16-'FS & Trend Analysis'!D16)/'FS & Trend Analysis'!D16 -> 0.083573487 | E16: =('FS & Trend Analysis'!D16-'FS & Trend Analysis'!E16)/'FS & Trend Analysis'!E16 -> 0.13152174 | F16: =('FS & Trend Analysis'!E16-'FS & Trend Analysis'!F16)/'FS & Trend Analysis'!F16 -> 0.33526851 | G16: =('FS & Trend Analysis'!F16-'FS & Trend Analysis'!G16)/'FS & Trend Analysis'!G16 -> 0.20538838
B17: Other expenses | C17: =('FS & Trend Analysis'!B17-'FS & Trend Analysis'!C17)/'FS & Trend Analysis'!C17 -> 0.13212996 | D17: =('FS & Trend Analysis'!C17-'FS & Trend Analysis'!D17)/'FS & Trend Analysis'!D17 -> 0.024408284 | E17: =('FS & Trend Analysis'!D17-'FS & Trend Analysis'!E17)/'FS & Trend Analysis'!E17 -> -0.0029498525 | F17: =('FS & Trend Analysis'!E17-'FS & Trend Analysis'!F17)/'FS & Trend Analysis'!F17 -> 0.040675365 | G17: =('FS & Trend Analysis'!F17-'FS & Trend Analysis'!G17)/'FS & Trend Analysis'!G17 -> 0.023646791
B18: Total expenses | C18: =('FS & Trend Analysis'!B18-'FS & Trend Analysis'!C18)/'FS & Trend Analysis'!C18 -> 0.030863199 | D18: =('FS & Trend Analysis'!C18-'FS & Trend Analysis'!D18)/'FS & Trend Analysis'!D18 -> 0.043959292 | E18: =('FS & Trend Analysis'!D18-'FS & Trend Analysis'!E18)/'FS & Trend Analysis'!E18 -> -0.094728392 | F18: =('FS & Trend Analysis'!E18-'FS & Trend Analysis'!F18)/'FS & Trend Analysis'!F18 -> -0.10641452 | G18: =('FS & Trend Analysis'!F18-'FS & Trend Analysis'!G18)/'FS & Trend Analysis'!G18 -> 0.11988768
B20: EBITDA | C20: =('FS & Trend Analysis'!B20-'FS & Trend Analysis'!C20)/'FS & Trend Analysis'!C20 -> 0.15619968 | D20: =('FS & Trend Analysis'!C20-'FS & Trend Analysis'!D20)/'FS & Trend Analysis'!D20 -> 0.21585903 | E20: =('FS & Trend Analysis'!D20-'FS & Trend Analysis'!E20)/'FS & Trend Analysis'!E20 -> 0.3683858 | F20: =('FS & Trend Analysis'!E20-'FS & Trend Analysis'!F20)/'FS & Trend Analysis'!F20 -> -0.025965553 | G20: =('FS & Trend Analysis'!F20-'FS & Trend Analysis'!G20)/'FS & Trend Analysis'!G20 -> 0.4141526
B21: Depreciation and amortisation expense | C21: =('FS & Trend Analysis'!B21-'FS & Trend Analysis'!C21)/'FS & Trend Analysis'!C21 -> 0.032846715 | D21: =('FS & Trend Analysis'!C21-'FS & Trend Analysis'!D21)/'FS & Trend Analysis'!D21 -> 0.037878788 | E21: =('FS & Trend Analysis'!D21-'FS & Trend Analysis'!E21)/'FS & Trend Analysis'!E21 -> -0.025830258 | F21: =('FS & Trend Analysis'!E21-'FS & Trend Analysis'!F21)/'FS & Trend Analysis'!F21 -> -0.062283737 | G21: =('FS & Trend Analysis'!F21-'FS & Trend Analysis'!G21)/'FS & Trend Analysis'!G21 -> 0.15924589
B22: EBIT | C22: =('FS & Trend Analysis'!B22-'FS & Trend Analysis'!C22)/'FS & Trend Analysis'!C22 -> 0.17149321 | D22: =('FS & Trend Analysis'!C22-'FS & Trend Analysis'!D22)/'FS & Trend Analysis'!D22 -> 0.24227094 | E22: =('FS & Trend Analysis'!D22-'FS & Trend Analysis'!E22)/'FS & Trend Analysis'!E22 -> 0.45581015 | F22: =('FS & Trend Analysis'!E22-'FS & Trend Analysis'!F22)/'FS & Trend Analysis'!F22 -> -0.017526934 | G22: =('FS & Trend Analysis'!F22-'FS & Trend Analysis'!G22)/'FS & Trend Analysis'!G22 -> 0.49029475
B23: Finance costs | C23: =('FS & Trend Analysis'!B23-'FS & Trend Analysis'!C23)/'FS & Trend Analysis'!C23 -> 0.7752809 | D23: =('FS & Trend Analysis'!C23-'FS & Trend Analysis'!D23)/'FS & Trend Analysis'!D23 -> 0.17105263 | E23: =('FS & Trend Analysis'!D23-'FS & Trend Analysis'!E23)/'FS & Trend Analysis'!E23 -> -0.26923077 | F23: =('FS & Trend Analysis'!E23-'FS & Trend Analysis'!F23)/'FS & Trend Analysis'!F23 -> 0.18181818 | G23: =('FS & Trend Analysis'!F23-'FS & Trend Analysis'!G23)/'FS & Trend Analysis'!G23 -> -0.46924005
B24: PBT before profits of JVs | C24: =('FS & Trend Analysis'!B24-'FS & Trend Analysis'!C24)/'FS & Trend Analysis'!C24 -> 0.14615747 | D24: =('FS & Trend Analysis'!C24-'FS & Trend Analysis'!D24)/'FS & Trend Analysis'!D24 -> 0.24544921 | E24: =('FS & Trend Analysis'!D24-'FS & Trend Analysis'!E24)/'FS & Trend Analysis'!E24 -> 0.52325581 | F24: =('FS & Trend Analysis'!E24-'FS & Trend Analysis'!F24)/'FS & Trend Analysis'!F24 -> -0.03270462 | G24: =('FS & Trend Analysis'!F24-'FS & Trend Analysis'!G24)/'FS & Trend Analysis'!G24 -> 0.72816986
B25: Add: Share of Profits of JVs
B26: PBT & Exceptional Items | C26: =('FS & Trend Analysis'!B26-'FS & Trend Analysis'!C26)/'FS & Trend Analysis'!C26 -> 0.14615747 | D26: =('FS & Trend Analysis'!C26-'FS & Trend Analysis'!D26)/'FS & Trend Analysis'!D26 -> 0.24544921 | E26: =('FS & Trend Analysis'!D26-'FS & Trend Analysis'!E26)/'FS & Trend Analysis'!E26 -> 0.52325581 | F26: =('FS & Trend Analysis'!E26-'FS & Trend Analysis'!F26)/'FS & Trend Analysis'!F26 -> -0.03270462 | G26: =('FS & Trend Analysis'!F26-'FS & Trend Analysis'!G26)/'FS & Trend Analysis'!G26 -> 0.72816986
B27: Exceptional Items | C27: =('FS & Trend Analysis'!B27-'FS & Trend Analysis'!C27)/'FS & Trend Analysis'!C27 -> 0.4 | D27: =('FS & Trend Analysis'!C27-'FS & Trend Analysis'!D27)/'FS & Trend Analysis'!D27 -> 2.8235294 | E27: =('FS & Trend Analysis'!D27-'FS & Trend Analysis'!E27)/'FS & Trend Analysis'!E27 -> -1.0994152 | F27: =('FS & Trend Analysis'!E27-'FS & Trend Analysis'!F27)/'FS & Trend Analysis'!F27 -> -2.0961538 | G27: =('FS & Trend Analysis'!F27-'FS & Trend Analysis'!G27)/'FS & Trend Analysis'!G27 -> 0.030383091
B28: PBT | C28: =('FS & Trend Analysis'!B28-'FS & Trend Analysis'!C28)/'FS & Trend Analysis'!C28 -> 0.1381323 | D28: =('FS & Trend Analysis'!C28-'FS & Trend Analysis'!D28)/'FS & Trend Analysis'!D28 -> 0.21945433 | E28: =('FS & Trend Analysis'!D28-'FS & Trend Analysis'!E28)/'FS & Trend Analysis'!E28 -> 0.30799069 | F28: =('FS & Trend Analysis'!E28-'FS & Trend Analysis'!F28)/'FS & Trend Analysis'!F28 -> 0.28925785 | G28: =('FS & Trend Analysis'!F28-'FS & Trend Analysis'!G28)/'FS & Trend Analysis'!G28 -> 0.93235408
B29: Tax | C29: =('FS & Trend Analysis'!B29-'FS & Trend Analysis'!C29)/'FS & Trend Analysis'!C29 -> 0.024096386 | D29: =('FS & Trend Analysis'!C29-'FS & Trend Analysis'!D29)/'FS & Trend Analysis'!D29 -> 0.3315508 | E29: =('FS & Trend Analysis'!D29-'FS & Trend Analysis'!E29)/'FS & Trend Analysis'!E29 -> 0.57805907 | F29: =('FS & Trend Analysis'!E29-'FS & Trend Analysis'!F29)/'FS & Trend Analysis'!F29 -> 0.48125 | G29: =('FS & Trend Analysis'!F29-'FS & Trend Analysis'!G29)/'FS & Trend Analysis'!G29 -> 0.0081915564
B30: PAT | C30: =('FS & Trend Analysis'!B30-'FS & Trend Analysis'!C30)/'FS & Trend Analysis'!C30 -> 0.1745828 | D30: =('FS & Trend Analysis'!C30-'FS & Trend Analysis'!D30)/'FS & Trend Analysis'!D30 -> 0.1875 | E30: =('FS & Trend Analysis'!D30-'FS & Trend Analysis'!E30)/'FS & Trend Analysis'!E30 -> 0.24714829 | F30: =('FS & Trend Analysis'!E30-'FS & Trend Analysis'!F30)/'FS & Trend Analysis'!F30 -> 0.25267921 | G30: =('FS & Trend Analysis'!F30-'FS & Trend Analysis'!G30)/'FS & Trend Analysis'!G30 -> 1.3412322
B31: Less: Share of Minority Interest
B32: PAT for Equity Shareholders | C32: =('FS & Trend Analysis'!B32-'FS & Trend Analysis'!C32)/'FS & Trend Analysis'!C32 -> 0.1745828 | D32: =('FS & Trend Analysis'!C32-'FS & Trend Analysis'!D32)/'FS & Trend Analysis'!D32 -> 0.1875 | E32: =('FS & Trend Analysis'!D32-'FS & Trend Analysis'!E32)/'FS & Trend Analysis'!E32 -> 0.24714829 | F32: =('FS & Trend Analysis'!E32-'FS & Trend Analysis'!F32)/'FS & Trend Analysis'!F32 -> 0.25267921 | G32: =('FS & Trend Analysis'!F32-'FS & Trend Analysis'!G32)/'FS & Trend Analysis'!G32 -> 1.3412322
B33: Dividend | C33: =('FS & Trend Analysis'!B33-'FS & Trend Analysis'!C33)/'FS & Trend Analysis'!C33 -> 2.6085714 | D33: =('FS & Trend Analysis'!C33-'FS & Trend Analysis'!D33)/'FS & Trend Analysis'!D33 -> 0.20274914 | E33: =('FS & Trend Analysis'!D33-'FS & Trend Analysis'!E33)/'FS & Trend Analysis'!E33 -> #DIV/0! | F33: =('FS & Trend Analysis'!E33-'FS & Trend Analysis'!F33)/'FS & Trend Analysis'!F33 -> #DIV/0! | G33: =('FS & Trend Analysis'!F33-'FS & Trend Analysis'!G33)/'FS & Trend Analysis'!G33 -> #DIV/0!
B34: Tax Rate (%) | C34: =('FS & Trend Analysis'!B34-'FS & Trend Analysis'!C34)/'FS & Trend Analysis'!C34 -> -0.10019565 | D34: =('FS & Trend Analysis'!C34-'FS & Trend Analysis'!D34)/'FS & Trend Analysis'!D34 -> 0.091923469 | E34: =('FS & Trend Analysis'!D34-'FS & Trend Analysis'!E34)/'FS & Trend Analysis'!E34 -> 0.20647577 | F34: =('FS & Trend Analysis'!E34-'FS & Trend Analysis'!F34)/'FS & Trend Analysis'!F34 -> 0.1489168 | G34: =('FS & Trend Analysis'!F34-'FS & Trend Analysis'!G34)/'FS & Trend Analysis'!G34 -> -0.47825734
B39: Comparative Balance Sheet
B40: Particulars | C40: 46112 | D40: 45747 | E40: 45382 | F40: 45016 | G40: 44651
B41: Equity & Liabilities
B42: Share capital | C42: =('FS & Trend Analysis'!B40-'FS & Trend Analysis'!C40)/'FS & Trend Analysis'!C40 -> 0 | D42: =('FS & Trend Analysis'!C40-'FS & Trend Analysis'!D40)/'FS & Trend Analysis'!D40 -> 0 | E42: =('FS & Trend Analysis'!D40-'FS & Trend Analysis'!E40)/'FS & Trend Analysis'!E40 -> -0.0034364261 | F42: =('FS & Trend Analysis'!E40-'FS & Trend Analysis'!F40)/'FS & Trend Analysis'!F40 -> 0 | G42: =('FS & Trend Analysis'!F40-'FS & Trend Analysis'!G40)/'FS & Trend Analysis'!G40 -> 0.0013764625
B43: Share suspense | C43: =('FS & Trend Analysis'!B41-'FS & Trend Analysis'!C41)/'FS & Trend Analysis'!C41 -> #DIV/0! | D43: =('FS & Trend Analysis'!C41-'FS & Trend Analysis'!D41)/'FS & Trend Analysis'!D41 -> #DIV/0! | E43: =('FS & Trend Analysis'!D41-'FS & Trend Analysis'!E41)/'FS & Trend Analysis'!E41 -> #DIV/0! | F43: =('FS & Trend Analysis'!E41-'FS & Trend Analysis'!F41)/'FS & Trend Analysis'!F41 -> -1 | G43: =('FS & Trend Analysis'!F41-'FS & Trend Analysis'!G41)/'FS & Trend Analysis'!G41 -> #DIV/0!
B44: Other equity | C44: =('FS & Trend Analysis'!B42-'FS & Trend Analysis'!C42)/'FS & Trend Analysis'!C42 -> #DIV/0! | D44: =('FS & Trend Analysis'!C42-'FS & Trend Analysis'!D42)/'FS & Trend Analysis'!D42 -> #DIV/0! | E44: =('FS & Trend Analysis'!D42-'FS & Trend Analysis'!E42)/'FS & Trend Analysis'!E42 -> #DIV/0! | F44: =('FS & Trend Analysis'!E42-'FS & Trend Analysis'!F42)/'FS & Trend Analysis'!F42 -> #DIV/0! | G44: =('FS & Trend Analysis'!F42-'FS & Trend Analysis'!G42)/'FS & Trend Analysis'!G42 -> #DIV/0!
B45: Reserves and surplus | C45: =('FS & Trend Analysis'!B43-'FS & Trend Analysis'!C43)/'FS & Trend Analysis'!C43 -> 0.10886993 | D45: =('FS & Trend Analysis'!C43-'FS & Trend Analysis'!D43)/'FS & Trend Analysis'!D43 -> 0.13435025 | E45: =('FS & Trend Analysis'!D43-'FS & Trend Analysis'!E43)/'FS & Trend Analysis'!E43 -> 0.17571995 | F45: =('FS & Trend Analysis'!E43-'FS & Trend Analysis'!F43)/'FS & Trend Analysis'!F43 -> 0.22166512 | G45: =('FS & Trend Analysis'!F43-'FS & Trend Analysis'!G43)/'FS & Trend Analysis'!G43 -> 0.19221399
B46: Total Equity | C46: =('FS & Trend Analysis'!B44-'FS & Trend Analysis'!C44)/'FS & Trend Analysis'!C44 -> 0.10686635 | D46: =('FS & Trend Analysis'!C44-'FS & Trend Analysis'!D44)/'FS & Trend Analysis'!D44 -> 0.13155249 | E46: =('FS & Trend Analysis'!D44-'FS & Trend Analysis'!E44)/'FS & Trend Analysis'!E44 -> 0.17133485 | F46: =('FS & Trend Analysis'!E44-'FS & Trend Analysis'!F44)/'FS & Trend Analysis'!F44 -> 0.21502299 | G46: =('FS & Trend Analysis'!F44-'FS & Trend Analysis'!G44)/'FS & Trend Analysis'!G44 -> 0.18554328
B48: Non-Current Liabilities
B49: Borrowings | C49: =('FS & Trend Analysis'!B47-'FS & Trend Analysis'!C47)/'FS & Trend Analysis'!C47 -> #DIV/0! | D49: =('FS & Trend Analysis'!C47-'FS & Trend Analysis'!D47)/'FS & Trend Analysis'!D47 -> #DIV/0! | E49: =('FS & Trend Analysis'!D47-'FS & Trend Analysis'!E47)/'FS & Trend Analysis'!E47 -> -1 | F49: =('FS & Trend Analysis'!E47-'FS & Trend Analysis'!F47)/'FS & Trend Analysis'!F47 -> -0.66666667 | G49: =('FS & Trend Analysis'!F47-'FS & Trend Analysis'!G47)/'FS & Trend Analysis'!G47 -> #DIV/0!
...

Sheet Cash Flow Statement
A1: Cash Flow Statement
A3: Particulars
A4: Cash Flow from Operating Activities | B4: March 31, 2026 | C4: March 31, 2025 | D4: March 31, 2024 | E4: March 31, 2023 | F4: March 31, 2022
A5: Depreciation and amortisation expense | B5: 283 | C5: 274 | D5: 264 | E5: 270.6 | F5: 288.6
A6: Employee share-based payment expense | B6: 22 | C6: 17 | D6: 37 | E6: 23.3 | F6: 25.2
A7: Loss allowance on trade receivables, other assets and other financial assets (net) | B7: 35 | C7: -9 | D7: 41 | E7: -12 | F7: -12.9
A8: Provision on doubtful other assets | B8: 0 | C8: 0 | D8: 0 | E8: 17.3 | F8: 15.8
A9: Profit on redemption/sale of investments | B9: -77 | C9: -25 | D9: -42 | E9: -16.6 | F9: 0
A10: Increase in fair value of investments | B10: -31 | C10: -16 | D10: -18 | E10: -2.5 | F10: 0
A11: Finance costs | B11: 158 | C11: 89 | D11: 76 | E11: 103.9 | F11: 88
A12: Dividend income from a subsidiary | B12: -101 | C12: -120 | D12: -125 | E12: 0 | F12: 0
A13: Gain on disposal of property, plant and equipment (net) | B13: -22 | C13: -99 | D13: -13 | E13: -20.3 | F13: -12.3
A14: Interest income | B14: -76 | C14: -73 | D14: -39 | E14: -34.2 | F14: -19.4
A15: Interest on direct and indirect tax refund | B15: -1 | C15: -1 | D15: -87 | E15: 0 | F15: 0
A16: Interest income from loan to subsidiary and joint venture | B16: -1 | C16: -1 | D16: 0 | E16: 0 | F16: 0
... A29: Income taxes paid (net of refunds) | B29: -334 | C29: -173 | D29: -313 | E29: -296.5 | F29: -457.6
A30: Net cash from operating activities | B30: =B28+B29 -> 1483 | C30: =C28+C29 -> 1606 | D30: =D28+D29 -> 912 | E30: =E28+E29 -> 576.6 | F30: =F28+F29 -> 911.3
A32: Cash Flow from Investing Activities
A33: Purchase of property, plant and equipment and intangible assets | B33: -181 | C33: -162 | D33: -98 | E33: -139.7 | F33: -134.6
A34: Proceeds from sale of property, plant and equipment and investment property | B34: 253 | C34: 1 | D34: 20 | E34: 26.5 | F34: 38.3
A35: Purchase of current investments | B35: -1862 | C35: -1246 | D35: -760 | E35: -8529.5 | F35: -1435.6
A36: Redemption of current investments | B36: 1688 | C36: 1011 | D36: 478 | E36: 8752.3 | F36: 1213.5
A37: Investment in term deposits with banks | B37: -1113 | C37: -1083 | D37: -400 | E37: -101.3 | F37: 0
A38: Redemption of term deposits from banks | B38: 790 | C38: 395 | D38: 980 | E38: 25 | F38: 0
A39: Investment in an associate/subsidiary/joint ventures | B39: -97 | C39: -13 | D39: -15 | E39: -31.5 | F39: 0
A40: Loans given to subsidiaries and joint ventures | B40: 0 | C40: -18 | D40: -29 | E40: -326.3 | F40: -249.9
A41: Repayment of loans by subsidiary and joint venture | B41: 18 | C41: 0 | D41: 121 | E41: 361.3 | F41: 321
A42: Repayment of loans given to others | B42: 3 | C42: 7 | D42: 6 | E42: 3.2 | F42: 0
A43: Loans given to others | B43: 0 | C43: 0 | D43: 0 | E43: -8 | F43: -10
A44: Interest received | B44: 65 | C44: 38 | D44: 39 | E44: 20.4 | F44: 17
... A49: Proceeds from disposal of investment in an associate | B49: 0 | C49: 0 | D49: 0 | E49: 0 | F49: 0.5
A50: Net cash from operating activities | B50: =SUM(B33:B49) -> -335 | C50: =SUM(C33:C49) -> -950 | D50: =SUM(D33:D49) -> 467 | E50: =SUM(E33:E49) -> 902.4 | F50: =SUM(F33:F49) -> -230.9
A55: Cash Flow from Financing Activities
A56: Net proceeds / (repayment) of working capital loans | B56: 0 | C56: 0 | D56: 0 | E56: -339.2 | F56: -535.7
A57: Repayment of deferred sales tax liability | B57: 0 | C57: -1 | D57: -1 | E57: -1.4 | F57: -2
A58: Interest paid on borrowings | B58: 0 | C58: 0 | D58: 0 | E58: -20.3 | F58: -38
A59: Dividend paid | B59: -1263 | C59: -350 | D59: -291 | E59: 0 | F59: 0
A60: Principal repayment of lease liabilities | B60: -143 | C60: -137 | D60: -126 | E60: -124 | F60: -100.2
A61: Interest paid on lease liabilities | B61: -37 | C61: -40 | D61: -21 | E61: -16 | F61: -11.9
A62: Net cash (used) in financing activities | B62: =SUM(B56:B61) -> -1443 | C62: =SUM(C56:C61) -> -528 | D62: =SUM(D56:D61) -> -439 | E62: =SUM(E56:E61) -> -500.9 | F62: =SUM(F56:F61) -> -687.8
...

Sheet Shareholding
A2: Promoter Group | B2: 0.346
A3: Foreign Institutional Investors (FII) | B3: 0.343
A4: Non Resident Indians (NRIs) | B4: 0.004
A5: Indian Public | B5: 0.083
A6: Insurance companies | B6: 0.083
A7: Mutual Funds / UTI | B7: 0.082
A8: Bodies Corporate | B8: 0.014
A9: Financial Institutions / Banks | B9: 0.02
A10: Others | B10: 0.025

Sheet Line Item Meanings
A1: INCOME STATEMENT — Line Item Meanings
A3: Income
A4: Revenue from Operations | B4: The money the company earns from its core business — in Diageo India's case, this is the sale of alcoholic beverages (spirits, beer, wine). It includes excise duty collected from customers. This is the top line of the P&L.
A5: Other Income | B5: Earnings that do not come from the main business. Examples: interest earned on bank deposits, profit on sale of investments, dividend received from subsidiaries, rental income, or gains on foreign exchange.
A6: Total Income | B6: Revenue from Operations + Other Income. Represents the total money flowing into the company during the year from all sources.
A8: Expenses
A9: Cost of Materials Consumed (Raw Material) | B9: The cost of raw materials (grain, molasses, glass bottles, packaging, etc.) used up during the year to manufacture the products. Formula: Opening stock of raw materials + Purchases − Closing stock.
A10: Purchase of Stock-in-Trade | B10: Cost of buying finished goods from outside for resale without any further manufacturing — for example, imported scotch or wine bought and sold as-is.
A11: Change in Inventories of FG, WIP & Stock-in-Trade | B11: Adjusts expenses to reflect actual production cost. If closing inventory > opening inventory (production exceeded sales), it is negative (reduces total expense). If the opposite, it is positive (adds to expense).
A12: Excise Duty | B12: Government tax levied on the manufacture/sale of alcoholic beverages. This is the single largest expense for liquor companies in India and is passed on to consumers as part of MRP.
A13: Employee Benefits Expense | B13: All costs related to employees — salaries & wages, bonus, PF/gratuity contributions, ESOP costs, staff welfare, and retirement benefit provisions.
A14: Advertisement and Sales Promotion | B14: Money spent on brand building, advertising (surrogate ads for liquor in India), sponsorships, trade promotions, point-of-sale materials, and consumer sampling.
A15: Other Expenses | B15: All remaining operating expenses — rent, repairs & maintenance, power & fuel, legal fees, audit fees, travel, insurance, IT costs, commission to distributors, freight & transport, etc.
A16: Total Expenses | B16: Sum of all the expense items above. Represents the total cost the company incurred to run its operations during the year.
A18: Profitability Measures
A19: EBITDA (Earnings Before Interest, Tax, Depreciation & Amortisation) | B19: Total Income minus Total Expenses (before deducting depreciation, interest, and tax). Shows the profit generated purely from operations — the best measure of operating cash-generating ability.
A20: Depreciation and Amortisation Expense | B20: Non-cash charge that spreads the cost of fixed assets (plant, machinery, buildings) and intangible assets (software, licenses) over their useful life. Reflects wear-and-tear and obsolescence.
A21: EBIT (Earnings Before Interest and Tax) | B21: EBITDA minus Depreciation. Shows operating profit after accounting for asset usage but before financing costs and taxes. Also called Operating Profit.
A22: Finance Costs | B22: Interest and other charges paid on borrowed money — includes interest on bank loans, lease liabilities, commercial paper, and any other debt instruments.
A23: PBT before Profits of JVs | B23: Profit Before Tax calculated before adding the company's share of profit/loss from joint ventures. Equals EBIT minus Finance Costs.
A24: Add: Share of Profits of JVs | B24: The company's proportionate share of net profit or loss from joint ventures accounted under the equity method. Zero means no active JV contributing profit.
A25: PBT & Exceptional Items | B25: Profit Before Tax before adjusting for one-time exceptional items. This is the recurring operating profitability number.
A26: Exceptional Items | B26: One-off, non-recurring gains or losses — such as profit/loss on sale of a factory, impairment of goodwill, restructuring charges, or legal settlement costs. Shown separately so analysts can see the 'clean' recurring profit.
A27: PBT (Profit Before Tax) | B27: The profit after all expenses including exceptional items but before paying income tax. PBT = PBT & Exceptional Items + Exceptional Items.
A28: Tax | B28: Income tax expense for the year — includes current tax (payable now) and deferred tax (timing differences between book profit and taxable profit).
A29: PAT (Profit After Tax) | B29: The bottom line — net profit remaining after all expenses and taxes. This is what belongs to the shareholders of the company.
A30: Less: Share of Minority Interest | B30: Portion of PAT that belongs to outside (minority) shareholders of subsidiaries — not to the parent company's shareholders. Zero means the company owns 100% of all subsidiaries.
... A33: Tax Rate (%) | B33: Effective tax rate = Tax / PBT. Shows what percentage of pre-tax profit goes to the government. Varies due to deferred tax adjustments, tax incentives, and prior-period items.
A36: BALANCE SHEET — Line Item Meanings
A38: Equity & Liabilities
A39: Share Capital | B39: The face value of all equity shares issued by the company. For Diageo India, each share has a face value of ₹10. This rarely changes unless new shares are issued or bought back.
A40: Share Suspense | B40: Shares allotted but pending final settlement formalities (e.g., ESOP shares awaiting exercise completion). Typically a very small or zero amount.
A41: Reserves and Surplus (Other Equity) | B41: Accumulated retained earnings over the years (profits not paid out as dividends), plus share premium, general reserve, and other reserves. This is the shareholders' wealth built up inside the company.
A42: Total Equity | B42: Share Capital + Share Suspense + Reserves & Surplus. Represents the net worth — the shareholders' total claim on the company's assets after all liabilities are paid.
A44: Non-Current Liabilities (due after more than 1 year)
A45: Borrowings (Non-Current) | B45: Long-term loans from banks or financial institutions that are due for repayment after more than one year. Zero means the company has no long-term debt — a sign of strong financial health.
A46: Lease Liabilities (Non-Current) | B46: The long-term portion of obligations under lease agreements (warehouses, offices, vehicles). Under Ind AS 116, operating leases are now recorded on the balance sheet.
A47: Provisions (Non-Current) | B47: Amounts set aside for known future obligations that will be settled beyond one year — such as employee gratuity, long-term leave encashment, or asset retirement obligations.
A48: Total Non-Current Liabilities | B48: Sum of all long-term obligations. A lower figure relative to equity means the company relies less on long-term debt to fund its operations.
A50: Current Liabilities (due within 1 year)
...
